Workbook
Name ACTION: #REF!

Sheet Cover
B2: TEST CASE
B3: Version: | C3: 1.0
B4: Issue date: | C4: 46257
B6: Project Name: | C6: SpringMediCare
B7: Project Code: | C7: SMC
B10: Lịch sử thay đổi
B11: Ngày | C11: Phiên bản | D11: Vị trí thay đổi | E11: Mô tả thay đổi | F11: Người thực hiện
B12: 46213 | C12: 1.0 | D12: LOG | E12: Kiểm thử lần đầu chức năng Đăng nhập: 10 test case, gồm 9 Pass và 1 Fail; sau khi khắc phục, test case lỗi được Retest và đạt Pass. | F12: Dương Lê Kim Phụng
B13: 46218 | C13: 1.1 | D13: REGISTER | E13: Kiểm thử lần đầu chức năng Đăng ký: 19 test case, gồm 11 Pass và 8 Fail. | F13: Dương Lê Kim Phụng
B14: 46219 | C14: 1.2 | D14: REGISTER | E14: Retest 8 test case Đăng ký bị Fail sau khi khắc phục; tất cả đều đạt Pass. | F14: Dương Lê Kim Phụng
B15: 46226 | C15: 1.3 | D15: BOOKING | E15: Kiểm thử lần đầu chức năng Đặt lịch: 8 test case, gồm 7 Pass và 1 Fail; test case lỗi được Retest và đạt Pass. | F15: Dương Lê Kim Phụng
B16: 46232 | C16: 1.4 | D16: APPOINTMENT | E16: Kiểm thử lần đầu chức năng Quản lý lịch hẹn: 9 test case, gồm 5 Pass và 4 Fail. | F16: Dương Lê Kim Phụng
B17: 46233 | C17: 1.5 | D17: APPOINTMENT, MEDICAL | E17: Retest các test case Lịch hẹn đã được khắc phục; đồng thời thực hiện kiểm thử lần đầu chức năng Hồ sơ y tế với 9 test case, gồm 7 Pass và 2 Fail. | F17: Dương Lê Kim Phụng
B18: 46234 | C18: 1.6 | D18: MEDICAL | E18: Retest 2 test case Hồ sơ y tế bị Fail sau khi khắc phục; cả 2 đều đạt Pass. | F18: Dương Lê Kim Phụng
B19: 46240 | C19: 1.7 | D19: DS_ADMIN | E19: Kiểm thử lần đầu chức năng Quản lý lịch làm việc bác sĩ; ghi nhận các test case Pass và các trường hợp Fail cần khắc phục. | F19: Dương Lê Kim Phụng
B20: 46241 | C20: 1.8 | D20: DS_ADMIN | E20: Retest các test case Quản lý lịch làm việc bác sĩ đã được khắc phục; các trường hợp được kiểm tra lại đạt Pass. | F20: Dương Lê Kim Phụng
B21: 46242 | C21: 1.9 | D21: DS_ADMIN | E21: Tiếp tục kiểm thử chức năng Quản lý lịch làm việc bác sĩ và Retest trường hợp lỗi sau khi khắc phục. | F21: Dương Lê Kim Phụng
B22: 46245 | C22: 1.10 | D22: MYAPPOINTMENT | E22: Kiểm thử chức năng Lịch hẹn của tôi: 5 test case và tất cả đều đạt Pass. | F22: Dương Lê Kim Phụng
B23: 46246 | C23: 1.11 | D23: HISTORY | E23: Kiểm thử lần đầu chức năng Lịch sử khám bệnh; ghi nhận 1 test case Fail cần khắc phục. | F23: Dương Lê Kim Phụng
... B30: 46257 | C30: 2,0 | D30: TEST SUMMARY, Test Report, Cover | E30: Tổng hợp kết quả kiểm thử, cập nhật Test Summary, Test Report và hoàn thiện tài liệu test case. | F30: Dương Lê Kim Phụng

Sheet TEST SUMMARY
A3: TEST SUMMARY
B5: Project Name: SpringMediCareWeb - Testing
B7: Test Result Summary:
B9: No. | C9: Module | D9: Total TC | E9: Initial Pass | F9: Initial Fail | G9: Retest Pass | H9: Final Pass | I9: Final Fail
B10: 1 | C10: Login | D10: =COUNTIF(LOG!A:A,"TC-*") -> 10 | E10: =COUNTIF(LOG!I:I,"Pass") -> 9 | F10: =COUNTIF(LOG!I:I,"Fail") -> 1 | G10: =COUNTIF(LOG!L:L,"Pass") -> 1 | H10: =COUNTIF(LOG!I:I,"Pass")+COUNTIFS(LOG!I:I,"Fail",LOG!L:L,"Pass") -> 10 | I10: =COUNTIFS(LOG!I:I,"Fail",LOG!L:L,"<>Pass") -> 0
B11: 2 | C11: Register | D11: =COUNTIF(REGISTER!A:A,"TC-*") -> 19 | E11: =COUNTIF(REGISTER!I:I,"Pass") -> 11 | F11: =COUNTIF(REGISTER!I:I,"Fail") -> 8 | G11: =COUNTIF(REGISTER!L:L,"Pass") -> 8 | H11: =COUNTIF(REGISTER!I:I,"Pass")+COUNTIFS(REGISTER!I:I,"Fail",REGISTER!L:L,"Pass") -> 19 | I11: =COUNTIFS(REGISTER!I:I,"Fail",REGISTER!L:L,"<>Pass") -> 0
B12: 3 | C12: Booking | D12: =COUNTIF(BOOKING!A:A,"TC-*") -> 10 | E12: =COUNTIF(BOOKING!I:I,"Pass") -> 8 | F12: =COUNTIF(BOOKING!I:I,"Fail") -> 2 | G12: =COUNTIF(BOOKING!L:L,"Pass") -> 1 | H12: =COUNTIF(BOOKING!I:I,"Pass")+COUNTIFS(BOOKING!I:I,"Fail",BOOKING!L:L,"Pass") -> 9 | I12: =COUNTIFS(BOOKING!I:I,"Fail",BOOKING!L:L,"<>Pass") -> 1
B13: 4 | C13: Appointment | D13: =COUNTIF(APPOINTMENT!A:A,"TC-*") -> 9 | E13: =COUNTIF(APPOINTMENT!I:I,"Pass") -> 5 | F13: =COUNTIF(APPOINTMENT!I:I,"Fail") -> 4 | G13: =COUNTIF(APPOINTMENT!L:L,"Pass") -> 3 | H13: =COUNTIF(APPOINTMENT!I:I,"Pass")+COUNTIFS(APPOINTMENT!I:I,"Fail",APPOINTMENT!L:L,"Pass") -> 8 | I13: =COUNTIFS(APPOINTMENT!I:I,"Fail",APPOINTMENT!L:L,"<>Pass") -> 1
B14: 5 | C14: Medical | D14: =COUNTIF(MEDICAL!A:A,"TC-*") -> 9 | E14: =COUNTIF(MEDICAL!I:I,"Pass") -> 7 | F14: =COUNTIF(MEDICAL!I:I,"Fail") -> 2 | G14: =COUNTIF(MEDICAL!L:L,"Pass") -> 2 | H14: =COUNTIF(MEDICAL!I:I,"Pass")+COUNTIFS(MEDICAL!I:I,"Fail",MEDICAL!L:L,"Pass") -> 9 | I14: =COUNTIFS(MEDICAL!I:I,"Fail",MEDICAL!L:L,"<>Pass") -> 0
B15: 6 | C15: Doctor Schedule Admin | D15: =COUNTIF(DS_ADMIN!A:A,"TC-*") -> 20 | E15: =COUNTIF(DS_ADMIN!I:I,"Pass") -> 13 | F15: =COUNTIF(DS_ADMIN!I:I,"Fail") -> 7 | G15: =COUNTIF(DS_ADMIN!L:L,"Pass") -> 6 | H15: =COUNTIF(DS_ADMIN!I:I,"Pass")+COUNTIFS(DS_ADMIN!I:I,"Fail",DS_ADMIN!L:L,"Pass") -> 19 | I15: =COUNTIFS(DS_ADMIN!I:I,"Fail",DS_ADMIN!L:L,"<>Pass") -> 1
B16: 7 | C16: My Appointment | D16: =COUNTIF(MYAPPOINTMENT!A:A,"TC-*") -> 5 | E16: =COUNTIF(MYAPPOINTMENT!I:I,"Pass") -> 5 | F16: =COUNTIF(MYAPPOINTMENT!I:I,"Fail") -> 0 | G16: =COUNTIF(MYAPPOINTMENT!L:L,"Pass") -> 0 | H16: =COUNTIF(MYAPPOINTMENT!I:I,"Pass")+COUNTIFS(MYAPPOINTMENT!I:I,"Fail",MYAPPOINTMENT!L:L,"Pass") -> 5 | I16: =COUNTIFS(MYAPPOINTMENT!I:I,"Fail",MYAPPOINTMENT!L:L,"<>Pass") -> 0
B17: 8 | C17: History | D17: =COUNTIF(HISTORY!A:A,"TC-*") -> 6 | E17: =COUNTIF(HISTORY!I:I,"Pass") -> 5 | F17: =COUNTIF(HISTORY!I:I,"Fail") -> 1 | G17: =COUNTIF(HISTORY!L:L,"Pass") -> 1 | H17: =COUNTIF(HISTORY!I:I,"Pass")+COUNTIFS(HISTORY!I:I,"Fail",HISTORY!L:L,"Pass") -> 6 | I17: =COUNTIFS(HISTORY!I:I,"Fail",HISTORY!L:L,"<>Pass") -> 0
B18: 9 | C18: Work Schedule | D18: =COUNTIF(WORKSCHEDULE!A:A,"TC-*") -> 5 | E18: =COUNTIF(WORKSCHEDULE!I:I,"Pass") -> 5 | F18: =COUNTIF(WORKSCHEDULE!I:I,"Fail") -> 0 | G18: =COUNTIF(WORKSCHEDULE!L:L,"Pass") -> 0 | H18: =COUNTIF(WORKSCHEDULE!I:I,"Pass")+COUNTIFS(WORKSCHEDULE!I:I,"Fail",WORKSCHEDULE!L:L,"Pass") -> 5 | I18: =COUNTIFS(WORKSCHEDULE!I:I,"Fail",WORKSCHEDULE!L:L,"<>Pass") -> 0
B19: 10 | C19: Notification | D19: =COUNTIF(NOTIFICATION!A:A,"TC-*") -> 9 | E19: =COUNTIF(NOTIFICATION!I:I,"Pass") -> 4 | F19: =COUNTIF(NOTIFICATION!I:I,"Fail") -> 5 | G19: =COUNTIF(NOTIFICATION!L:L,"Pass") -> 4 | H19: =COUNTIF(NOTIFICATION!I:I,"Pass")+COUNTIFS(NOTIFICATION!I:I,"Fail",NOTIFICATION!L:L,"Pass") -> 8 | I19: =COUNTIFS(NOTIFICATION!I:I,"Fail",NOTIFICATION!L:L,"<>Pass") -> 1
B20: 11 | C20: Doctor | D20: =COUNTIF(DOCTOR!A:A,"TC-*") -> 4 | E20: =COUNTIF(DOCTOR!I:I,"Pass") -> 4 | F20: =COUNTIF(DOCTOR!I:I,"Fail") -> 0 | G20: =COUNTIF(DOCTOR!L:L,"Pass") -> 0 | H20: =COUNTIF(DOCTOR!I:I,"Pass")+COUNTIFS(DOCTOR!I:I,"Fail",DOCTOR!L:L,"Pass") -> 4 | I20: =COUNTIFS(DOCTOR!I:I,"Fail",DOCTOR!L:L,"<>Pass") -> 0
B21: 12 | C21: Specialty | D21: =COUNTIF(SPECIALTY!A:A,"TC-*") -> 5 | E21: =COUNTIF(SPECIALTY!I:I,"Pass") -> 5 | F21: =COUNTIF(SPECIALTY!I:I,"Fail") -> 0 | G21: =COUNTIF(SPECIALTY!L:L,"Pass") -> 0 | H21: =COUNTIF(SPECIALTY!I:I,"Pass")+COUNTIFS(SPECIALTY!I:I,"Fail",SPECIALTY!L:L,"Pass") -> 5 | I21: =COUNTIFS(SPECIALTY!I:I,"Fail",SPECIALTY!L:L,"<>Pass") -> 0
B22: 13 | C22: Drug Category | D22: =COUNTIF(DRUG_CATEGORY!A:A,"TC-*") -> 11 | E22: =COUNTIF(DRUG_CATEGORY!I:I,"Pass") -> 10 | F22: =COUNTIF(DRUG_CATEGORY!I:I,"Fail") -> 1 | G22: =COUNTIF(DRUG_CATEGORY!L:L,"Pass") -> 0 | H22: =COUNTIF(DRUG_CATEGORY!I:I,"Pass")+COUNTIFS(DRUG_CATEGORY!I:I,"Fail",DRUG_CATEGORY!L:L,"Pass") -> 10 | I22: =COUNTIFS(DRUG_CATEGORY!I:I,"Fail",DRUG_CATEGORY!L:L,"<>Pass") -> 1
B23: 14 | C23: Statistics | D23: =COUNTIF(STAT!A:A,"TC-*") -> 4 | E23: =COUNTIF(STAT!I:I,"Pass") -> 4 | F23: =COUNTIF(STAT!I:I,"Fail") -> 0 | G23: =COUNTIF(STAT!L:L,"Pass") -> 0 | H23: =COUNTIF(STAT!I:I,"Pass")+COUNTIFS(STAT!I:I,"Fail",STAT!L:L,"Pass") -> 4 | I23: =COUNTIFS(STAT!I:I,"Fail",STAT!L:L,"<>Pass") -> 0
B24: Tổng | D24: =SUM(D9:D23) -> 126 | E24: =SUM(E9:E23) -> 95 | F24: =SUM(F9:F23) -> 31 | G24: =SUM(G9:G23) -> 26 | H24: =SUM(H9:H23) -> 121 | I24: =SUM(I9:I23) -> 5

Sheet Test Report
A1: TEST REPORT
B3: Note: | C3: Final test execution summary after retesting.
B4: Date | C4: 46257
B7: No | C7: Module code | D7: Pass | E7: Fail | F7: Pending | G7: Number of test cases
B8: =ROW()-7 -> 1 | C8: =LOG!B4 -> AUTH - Login | D8: =COUNTIFS(LOG!A:A,"TC-*",LOG!L:L,"Pass")+COUNTIFS(LOG!A:A,"TC-*",LOG!L:L,"",LOG!I:I,"Pass") -> 10 | E8: =COUNTIFS(LOG!A:A,"TC-*",LOG!L:L,"Fail")+COUNTIFS(LOG!A:A,"TC-*",LOG!L:L,"",LOG!I:I,"Fail") -> 0 | F8: =COUNTIFS(LOG!A:A,"TC-*",LOG!L:L,"Pending")+COUNTIFS(LOG!A:A,"TC-*",LOG!L:L,"",LOG!I:I,"Pending") -> 0 | G8: =COUNTIF(LOG!A:A,"TC-*") -> 10
B9: =ROW()-7 -> 2 | C9: =REGISTER!B4 -> AUTH - Register | D9: =COUNTIFS(REGISTER!A:A,"TC-*",REGISTER!L:L,"Pass")+COUNTIFS(REGISTER!A:A,"TC-*",REGISTER!L:L,"",REGISTER!I:I,"Pass") -> 19 | E9: =COUNTIFS(REGISTER!A:A,"TC-*",REGISTER!L:L,"Fail")+COUNTIFS(REGISTER!A:A,"TC-*",REGISTER!L:L,"",REGISTER!I:I,"Fail") -> 0 | F9: =COUNTIFS(REGISTER!A:A,"TC-*",REGISTER!L:L,"Pending")+COUNTIFS(REGISTER!A:A,"TC-*",REGISTER!L:L,"",REGISTER!I:I,"Pending") -> 0 | G9: =COUNTIF(REGISTER!A:A,"TC-*") -> 19
B10: =ROW()-7 -> 3 | C10: =BOOKING!B4 -> BOOKING - Appointment Booking | D10: =COUNTIFS(BOOKING!A:A,"TC-*",BOOKING!L:L,"Pass")+COUNTIFS(BOOKING!A:A,"TC-*",BOOKING!L:L,"",BOOKING!I:I,"Pass") -> 9 | E10: =COUNTIFS(BOOKING!A:A,"TC-*",BOOKING!L:L,"Fail")+COUNTIFS(BOOKING!A:A,"TC-*",BOOKING!L:L,"",BOOKING!I:I,"Fail") -> 1 | F10: =COUNTIFS(BOOKING!A:A,"TC-*",BOOKING!L:L,"Pending")+COUNTIFS(BOOKING!A:A,"TC-*",BOOKING!L:L,"",BOOKING!I:I,"Pending") -> 0 | G10: =COUNTIF(BOOKING!A:A,"TC-*") -> 10
B11: =ROW()-7 -> 4 | C11: =APPOINTMENT!B4 -> APPOINTMENT - Appointment Management | D11: =COUNTIFS(APPOINTMENT!A:A,"TC-*",APPOINTMENT!L:L,"Pass")+COUNTIFS(APPOINTMENT!A:A,"TC-*",APPOINTMENT!L:L,"",APPOINTMENT!I:I,"Pass") -> 8 | E11: =COUNTIFS(APPOINTMENT!A:A,"TC-*",APPOINTMENT!L:L,"Fail")+COUNTIFS(APPOINTMENT!A:A,"TC-*",APPOINTMENT!L:L,"",APPOINTMENT!I:I,"Fail") -> 1 | F11: =COUNTIFS(APPOINTMENT!A:A,"TC-*",APPOINTMENT!L:L,"Pending")+COUNTIFS(APPOINTMENT!A:A,"TC-*",APPOINTMENT!L:L,"",APPOINTMENT!I:I,"Pending") -> 0 | G11: =COUNTIF(APPOINTMENT!A:A,"TC-*") -> 9
B12: =ROW()-7 -> 5 | C12: =MEDICAL!B4 -> MEDICAL - Medical Record Management | D12: =COUNTIFS(MEDICAL!A:A,"TC-*",MEDICAL!L:L,"Pass")+COUNTIFS(MEDICAL!A:A,"TC-*",MEDICAL!L:L,"",MEDICAL!I:I,"Pass") -> 9 | E12: =COUNTIFS(MEDICAL!A:A,"TC-*",MEDICAL!L:L,"Fail")+COUNTIFS(MEDICAL!A:A,"TC-*",MEDICAL!L:L,"",MEDICAL!I:I,"Fail") -> 0 | F12: =COUNTIFS(MEDICAL!A:A,"TC-*",MEDICAL!L:L,"Pending")+COUNTIFS(MEDICAL!A:A,"TC-*",MEDICAL!L:L,"",MEDICAL!I:I,"Pending") -> 0 | G12: =COUNTIF(MEDICAL!A:A,"TC-*") -> 9
B13: =ROW()-7 -> 6 | C13: =DS_ADMIN!B4 -> SCHEDULE - Doctor Schedule Management | D13: =COUNTIFS(DS_ADMIN!A:A,"TC-*",DS_ADMIN!L:L,"Pass")+COUNTIFS(DS_ADMIN!A:A,"TC-*",DS_ADMIN!L:L,"",DS_ADMIN!I:I,"Pass") -> 19 | E13: =COUNTIFS(DS_ADMIN!A:A,"TC-*",DS_ADMIN!L:L,"Fail")+COUNTIFS(DS_ADMIN!A:A,"TC-*",DS_ADMIN!L:L,"",DS_ADMIN!I:I,"Fail") -> 1 | F13: =COUNTIFS(DS_ADMIN!A:A,"TC-*",DS_ADMIN!L:L,"Pending")+COUNTIFS(DS_ADMIN!A:A,"TC-*",DS_ADMIN!L:L,"",DS_ADMIN!I:I,"Pending") -> 0 | G13: =COUNTIF(DS_ADMIN!A:A,"TC-*") -> 20
B14: =ROW()-7 -> 7 | C14: =MYAPPOINTMENT!B4 -> PATIENT - My Appointments | D14: =COUNTIFS(MYAPPOINTMENT!A:A,"TC-*",MYAPPOINTMENT!L:L,"Pass")+COUNTIFS(MYAPPOINTMENT!A:A,"TC-*",MYAPPOINTMENT!L:L,"",MYAPPOINTMENT!I:I,"Pass") -> 5 | E14: =COUNTIFS(MYAPPOINTMENT!A:A,"TC-*",MYAPPOINTMENT!L:L,"Fail")+COUNTIFS(MYAPPOINTMENT!A:A,"TC-*",MYAPPOINTMENT!L:L,"",MYAPPOINTMENT!I:I,"Fail") -> 0 | F14: =COUNTIFS(MYAPPOINTMENT!A:A,"TC-*",MYAPPOINTMENT!L:L,"Pending")+COUNTIFS(MYAPPOINTMENT!A:A,"TC-*",MYAPPOINTMENT!L:L,"",MYAPPOINTMENT!I:I,"Pending") -> 0 | G14: =COUNTIF(MYAPPOINTMENT!A:A,"TC-*") -> 5
B15: =ROW()-7 -> 8 | C15: =HISTORY!B4 -> MEDICAL - Medical History | D15: =COUNTIFS(HISTORY!A:A,"TC-*",HISTORY!L:L,"Pass")+COUNTIFS(HISTORY!A:A,"TC-*",HISTORY!L:L,"",HISTORY!I:I,"Pass") -> 6 | E15: =COUNTIFS(HISTORY!A:A,"TC-*",HISTORY!L:L,"Fail")+COUNTIFS(HISTORY!A:A,"TC-*",HISTORY!L:L,"",HISTORY!I:I,"Fail") -> 0 | F15: =COUNTIFS(HISTORY!A:A,"TC-*",HISTORY!L:L,"Pending")+COUNTIFS(HISTORY!A:A,"TC-*",HISTORY!L:L,"",HISTORY!I:I,"Pending") -> 0 | G15: =COUNTIF(HISTORY!A:A,"TC-*") -> 6
B16: =ROW()-7 -> 9 | C16: =WORKSCHEDULE!B4 -> SCHEDULE - Doctor Work Schedule | D16: =COUNTIFS(WORKSCHEDULE!A:A,"TC-*",WORKSCHEDULE!L:L,"Pass")+COUNTIFS(WORKSCHEDULE!A:A,"TC-*",WORKSCHEDULE!L:L,"",WORKSCHEDULE!I:I,"Pass") -> 5 | E16: =COUNTIFS(WORKSCHEDULE!A:A,"TC-*",WORKSCHEDULE!L:L,"Fail")+COUNTIFS(WORKSCHEDULE!A:A,"TC-*",WORKSCHEDULE!L:L,"",WORKSCHEDULE!I:I,"Fail") -> 0 | F16: =COUNTIFS(WORKSCHEDULE!A:A,"TC-*",WORKSCHEDULE!L:L,"Pending")+COUNTIFS(WORKSCHEDULE!A:A,"TC-*",WORKSCHEDULE!L:L,"",WORKSCHEDULE!I:I,"Pending") -> 0 | G16: =COUNTIF(WORKSCHEDULE!A:A,"TC-*") -> 5
B17: =ROW()-7 -> 10 | C17: =NOTIFICATION!B4 -> NOTIFICATION - Patient Notifications | D17: =COUNTIFS(NOTIFICATION!A:A,"TC-*",NOTIFICATION!L:L,"Pass")+COUNTIFS(NOTIFICATION!A:A,"TC-*",NOTIFICATION!L:L,"",NOTIFICATION!I:I,"Pass") -> 8 | E17: =COUNTIFS(NOTIFICATION!A:A,"TC-*",NOTIFICATION!L:L,"Fail")+COUNTIFS(NOTIFICATION!A:A,"TC-*",NOTIFICATION!L:L,"",NOTIFICATION!I:I,"Fail") -> 1 | F17: =COUNTIFS(NOTIFICATION!A:A,"TC-*",NOTIFICATION!L:L,"Pending")+COUNTIFS(NOTIFICATION!A:A,"TC-*",NOTIFICATION!L:L,"",NOTIFICATION!I:I,"Pending") -> 0 | G17: =COUNTIF(NOTIFICATION!A:A,"TC-*") -> 9
B18: =ROW()-7 -> 11 | C18: =DOCTOR!B4 -> DOCTOR - Doctor Management | D18: =COUNTIFS(DOCTOR!A:A,"TC-*",DOCTOR!L:L,"Pass")+COUNTIFS(DOCTOR!A:A,"TC-*",DOCTOR!L:L,"",DOCTOR!I:I,"Pass") -> 4 | E18: =COUNTIFS(DOCTOR!A:A,"TC-*",DOCTOR!L:L,"Fail")+COUNTIFS(DOCTOR!A:A,"TC-*",DOCTOR!L:L,"",DOCTOR!I:I,"Fail") -> 0 | F18: =COUNTIFS(DOCTOR!A:A,"TC-*",DOCTOR!L:L,"Pending")+COUNTIFS(DOCTOR!A:A,"TC-*",DOCTOR!L:L,"",DOCTOR!I:I,"Pending") -> 0 | G18: =COUNTIF(DOCTOR!A:A,"TC-*") -> 4
B19: =ROW()-7 -> 12 | C19: =SPECIALTY!B4 -> SPECIALTY - Specialty Management | D19: =COUNTIFS(SPECIALTY!A:A,"TC-*",SPECIALTY!L:L,"Pass")+COUNTIFS(SPECIALTY!A:A,"TC-*",SPECIALTY!L:L,"",SPECIALTY!I:I,"Pass") -> 5 | E19: =COUNTIFS(SPECIALTY!A:A,"TC-*",SPECIALTY!L:L,"Fail")+COUNTIFS(SPECIALTY!A:A,"TC-*",SPECIALTY!L:L,"",SPECIALTY!I:I,"Fail") -> 0 | F19: =COUNTIFS(SPECIALTY!A:A,"TC-*",SPECIALTY!L:L,"Pending")+COUNTIFS(SPECIALTY!A:A,"TC-*",SPECIALTY!L:L,"",SPECIALTY!I:I,"Pending") -> 0 | G19: =COUNTIF(SPECIALTY!A:A,"TC-*") -> 5
B20: =ROW()-7 -> 13 | C20: =DRUG_CATEGORY!B4 -> DRUG - Drug Inventory Management | D20: =COUNTIFS(DRUG_CATEGORY!A:A,"TC-*",DRUG_CATEGORY!L:L,"Pass")+COUNTIFS(DRUG_CATEGORY!A:A,"TC-*",DRUG_CATEGORY!L:L,"",DRUG_CATEGORY!I:I,"Pass") -> 10 | E20: =COUNTIFS(DRUG_CATEGORY!A:A,"TC-*",DRUG_CATEGORY!L:L,"Fail")+COUNTIFS(DRUG_CATEGORY!A:A,"TC-*",DRUG_CATEGORY!L:L,"",DRUG_CATEGORY!I:I,"Fail") -> 1 | F20: =COUNTIFS(DRUG_CATEGORY!A:A,"TC-*",DRUG_CATEGORY!L:L,"Pending")+COUNTIFS(DRUG_CATEGORY!A:A,"TC-*",DRUG_CATEGORY!L:L,"",DRUG_CATEGORY!I:I,"Pending") -> 0 | G20: =COUNTIF(DRUG_CATEGORY!A:A,"TC-*") -> 11
B21: =ROW()-7 -> 14 | C21: =STAT!B4 -> STAT - Statistics and Reporting | D21: =COUNTIFS(STAT!A:A,"TC-*",STAT!L:L,"Pass")+COUNTIFS(STAT!A:A,"TC-*",STAT!L:L,"",STAT!I:I,"Pass") -> 4 | E21: =COUNTIFS(STAT!A:A,"TC-*",STAT!L:L,"Fail")+COUNTIFS(STAT!A:A,"TC-*",STAT!L:L,"",STAT!I:I,"Fail") -> 0 | F21: =COUNTIFS(STAT!A:A,"TC-*",STAT!L:L,"Pending")+COUNTIFS(STAT!A:A,"TC-*",STAT!L:L,"",STAT!I:I,"Pending") -> 0 | G21: =COUNTIF(STAT!A:A,"TC-*") -> 4
C22: Sub total | D22: =SUM(D8:D21) -> 121 | E22: =SUM(E8:E21) -> 5 | F22: =SUM(F8:F21) -> 0 | G22: =SUM(G8:G21) -> 126
C24: Test coverage | E24: =(D22+E22)*100/G22 -> 100 | F24: %
C25: Test successful coverage | E25: =D22*100/G22 -> 96.031746 | F25: %

Sheet LOG
A1: TEST CASE
A3: System Name： | B3: SpringMediCareWeb
A4: Module Code： | B4: AUTH - Login
A5: Test requirement: | B5: Login and Authentication
A6: Pass | B6: 9 | C6: Pending | D6: 0
A7: Fail | B7: 1 | C7: Number of test cases: | D7: 10
A9: ID | B9: Test Case Description | C9: Test Case Procedure | D9: Expected Results | G9: Actual Results | H9: Test date | I9: Status | J9: Note | K9: Retest Date | L9: Retest Status | M9: Retest Evidence
A12: 1. Kiểm tra đăng ký hợp lệ
A13: TC-LOGIN-001 | B13: Kiểm tra đăng nhập thành công bằng tên đăng nhập hợp lệ | C13: 1: Mở trang đăng nhập 2: Nhập tài khoản hợp lệ 3: Nhập đúng mật khẩu 4: Nhấn Đăng nhập 5: Kiểm tra đăng nhập thành công, chuyển đúng trang và hiển thị trạng thái đã đăng nhập | D13: Hệ thống đăng nhập thành công, chuyển đến trang chủ, hiển thị tên người dùng và nút Đăng xuất. | G13: TCLog1_1, TCLog1_2 | H13: 46213 | I13: Pass | J13: Đăng nhập thành công, hệ thống chuyển trang hiện giao diện người dùng
A14: TC-LOGIN-002 | B14: Kiểm tra đăng nhập thành công bằng email hợp lệ | C14: 1: Mở trang đăng nhập 2: Nhập email hợp lệ 3: Nhập đúng mật khẩu 4: Nhấn Đăng nhập 5: Kiểm tra đăng nhập thành công và chuyển đến trang phù hợp với vai trò | D14: Hệ thống đăng nhập thành công và chuyển đến trang chính đúng với vai trò người dùng | G14: TCLog2 | H14: 46213 | I14: Fail | J14: Hệ thống không cho đăng nhập bằng email đã tồn tại và hiển thị thông báo “Sai tên đăng nhập hoặc mật khẩu”. | K14: 46213 | L14: Pass | M14: TCLog2Retest_1,TCLog2Retest_2
A15: 2. Kiểm tra validation dữ liệu bắt buộc
A16: TC-LOGIN-003 | B16: Kiểm tra không thể đăng nhập khi bỏ trống tên đăng nhập | C16: 1: Mở trang đăng nhập 2: Để trống tên đăng nhập 3: Nhập mật khẩu 4: Nhấn Đăng nhập 5: Kiểm tra thông báo validation và xác nhận không đăng nhập | D16: Hệ thống hiển thị thông báo yêu cầu nhập tài khoản và không cho đăng nhập | G16: TCLog3 | H16: 46213 | I16: Pass | J16: Validation hoạt động đúng khi người dùng để trống tên đăng nhập.
A17: TC-LOGIN-004 | B17: Kiểm tra không thể đăng nhập khi bỏ trống mật khẩu | C17: 1: Mở trang đăng nhập 2: Nhập tên đăng nhập hợp lệ 3: Để trống mật khẩu 4: Nhấn Đăng nhập 5: Kiểm tra thông báo validation và xác nhận không đăng nhập | D17: Hệ thống hiển thị thông báo yêu cầu nhập mật khẩu và không cho đăng nhập | G17: TCLog4 | H17: 46213 | I17: Pass | J17: Validation hoạt động đúng khi người dùng để trống mật khẩu
A18: TC-LOGIN-005 | B18: Kiểm tra không thể đăng nhập khi bỏ trống tên đăng nhập và mật khẩu | C18: 1: Mở trang đăng nhập 2: Để trống tên đăng nhập 3: Để trống mật khẩu 4: Nhấn Đăng nhập 5: Kiểm tra validation các trường bắt buộc và xác nhận không đăng nhập | D18: Hệ thống hiển thị thông báo yêu cầu nhập đầy đủ thông tin đăng nhập | G18: TCLog5 | H18: 46213 | I18: Pass | J18: Validation hoạt động đúng khi người dùng để trống mật khẩu và tên đăng nhập
A19: 3. Kiểm tra dữ liệu đăng ký không hợp lệ
A20: TC-LOGIN-006 | B20: Kiểm tra không thể đăng nhập khi nhập sai mật khẩu | C20: 1: Mở trang đăng nhập 2: Nhập tên đăng nhập hợp lệ 3: Nhập mật khẩu sai 4: Nhấn Đăng nhập 5: Kiểm tra thông báo lỗi và xác nhận không đăng nhập | D20: Hệ thống không cho đăng nhập và hiển thị thông báo sai tài khoản hoặc mật khẩu | G20: TCLog6 | H20: 46213 | I20: Pass | J20: Validation hoạt động đúng khi người dùng nhập sai mật khẩu
A21: TC-LOGIN-007 | B21: Kiểm tra không thể đăng nhập với tài khoản không tồn tại | C21: 1: Mở trang đăng nhập 2: Nhập tài khoản không tồn tại 3: Nhập mật khẩu bất kỳ 4: Nhấn Đăng nhập 5: Kiểm tra thông báo lỗi và xác nhận không đăng nhập | D21: Hệ thống không cho đăng nhập và hiển thị thông báo sai tài khoản hoặc mật khẩu | G21: TCLog7 | H21: 46213 | I21: Pass | J21: Validation hoạt động đúng khi người dùng nhập sai tên đăng nhập
A22: 4. Kiểm tra xử lý sau khi đăng nhập
A23: TC-LOGIN-008 | B23: Kiểm tra đăng xuất thành công sau khi đã đăng nhập | C23: 1: Đăng nhập thành công 2: Nhấn Đăng xuất 3: Kiểm tra đăng xuất thành công và hệ thống chuyển về trạng thái chưa đăng nhập | D23: Hệ thống đăng xuất thành công và chuyển về trang đăng nhập hoặc trang chủ | G23: TCLog8_1, TCLog8_2 | H23: 46213 | I23: Pass | J23: Đăng nhập thành công, hệ thống chuyển trang hiện giao diện chưa đăng nhập
A24: TC-LOGIN-009 | B24: Kiểm tra không thể truy cập trang yêu cầu xác thực khi chưa đăng nhập | C24: 1: Đảm bảo người dùng chưa đăng nhập 2: Truy cập trực tiếp URL trang yêu cầu đăng nhập 3: Kiểm tra hệ thống chặn truy cập và chuyển về trang đăng nhập hoặc yêu cầu đăng nhập | D24: Hệ thống không cho truy cập và và hiện thông báo vui lòng đăng nhập | G24: TCLog9 | H24: 46213 | I24: Pass | J24: Hệ thống thực hiện đúng, không cho truy câp trang khi chưa đăng nhập
A25: TC-LOGIN-010 | B25: Kiểm tra trạng thái đăng nhập sau khi đăng xuất và quay lại trang trước | C25: 1: Đăng nhập thành công 2: Nhấn Đăng xuất 3: Nhấn nút Back của trình duyệt 4: Kiểm tra người dùng không thể quay lại trạng thái đã đăng nhập | D25: Hệ thống hiện trang chủ khi chưa đăng nhập | G25: TCLog10_1,TCLog10_2, TCLog10_3 | H25: 46213 | I25: Pass | J25: Hệ thống thực hiện đúng

Sheet REGISTER
A1: TEST CASE
A3: System Name： | B3: SpringMediCareWeb
A4: Module Code： | B4: AUTH - Register
A5: Test requirement: | B5: User Registration
A6: Pass | B6: 12 | C6: Pending | D6: 0
A7: Fail | B7: 7 | C7: Number of test cases: | D7: 19
A9: ID | B9: Test Case Description | C9: Test Case Procedure | D9: Expected Results | G9: Actual Results | H9: Test date | I9: Status | J9: Note | K9: Retest Date | L9: Retest Status | M9: Retest Evidence
A12: 1. Kiểm tra đăng ký hợp lệ
A13: TC-REGISTER-001 | B13: Kiểm tra đăng ký tài khoản với thông tin hợp lệ | C13: 1: Mở trang đăng ký. 2: Nhập đầy đủ thông tin hợp lệ. 3: Chọn ảnh đại diện hợp lệ. 4: Nhấn nút Đăng ký. 5: Kiểm tra kết quả sau khi nhấn Đăng ký. | D13: Hệ thống tạo tài khoản thành công, hiển thị thông báo phù hợp và chuyển người dùng đến trang đăng nhập. | G13: TCRegister1_1, TCRegister1_2, TCRegister1_3 | H13: 46218 | I13: Pass | J13: Đăng ký thành công, hệ thống chuyển trang đăng nhập
A14: 2. Kiểm tra validation dữ liệu bắt buộc
A15: TC-REGISTER-002 | B15: Kiểm tra đăng ký khi không chọn ảnh đại diện | C15: 1: Mở trang đăng ký. 2: Nhập đầy đủ thông tin hợp lệ. 3: Không chọn ảnh đại diện. 4: Nhấn nút Đăng ký. 5: Kiểm tra kết quả sau khi nhấn Đăng ký. | D15: Hệ thống không tạo tài khoản và hiển thị thông báo yêu cầu chọn ảnh đại diện. | G15: TCRegister2 | H15: 46218 | I15: Pass | J15: Hệ thống không cho đăng ký khi chưa chọn ảnh đại diện và hiển thị thông báo yêu cầu chọn ảnh.
A16: TC-REGISTER-003 | B16: Kiểm tra đăng ký khi bỏ trống họ | C16: 1: Mở trang đăng ký. 2: Để trống trường Họ. 3: Nhập hợp lệ các trường còn lại. 4: Nhấn nút Đăng ký. 5: Kiểm tra kết quả sau khi nhấn Đăng ký. | D16: Hệ thống không tạo tài khoản và hiển thị yêu cầu nhập họ. | G16: TCRegister3 | H16: 46218 | I16: Pass | J16: Hệ thống không tạo tài khoản và hiển thị yêu cầu nhập họ.
A17: TC-REGISTER-004 | B17: Kiểm tra đăng ký khi bỏ trống tên | C17: 1: Mở trang đăng ký. 2: Để trống trường Tên. 3: Nhập hợp lệ các trường còn lại. 4: Nhấn nút Đăng ký. 5: Kiểm tra kết quả sau khi nhấn Đăng ký. | D17: Hệ thống không tạo tài khoản và hiển thị yêu cầu nhập tên. | G17: TCRegister4 | H17: 46218 | I17: Pass | J17: Hệ thống không tạo tài khoản và hiển thị yêu cầu nhập tên.
A18: TC-REGISTER-005 | B18: Kiểm tra đăng ký khi bỏ trống email | C18: 1: Mở trang đăng ký. 2: Để trống trường Email. 3: Nhập hợp lệ các trường còn lại. 4: Nhấn nút Đăng ký. 5: Kiểm tra kết quả sau khi nhấn Đăng ký. | D18: Hệ thống không tạo tài khoản và hiển thị yêu cầu nhập email. | G18: TCRegister5 | H18: 46218 | I18: Pass | J18: Hệ thống không tạo tài khoản và hiển thị yêu cầu nhập email.
A19: TC-REGISTER-006 | B19: Kiểm tra đăng ký khi bỏ trống số điện thoại | C19: 1: Mở trang đăng ký. 2: Để trống trường Số điện thoại. 3: Nhập hợp lệ các trường còn lại. 4: Nhấn nút Đăng ký. 5: Kiểm tra kết quả sau khi nhấn Đăng ký. | D19: Hệ thống không tạo tài khoản và hiển thị yêu cầu nhập số điện thoại. | G19: TCRegister6 | H19: 46218 | I19: Pass | J19: Hệ thống không tạo tài khoản và hiển thị yêu cầu nhập số điện thoại.
A20: TC-REGISTER-007 | B20: Kiểm tra đăng ký khi bỏ trống tên đăng nhập | C20: 1: Mở trang đăng ký. 2: Để trống trường Tên đăng nhập. 3: Nhập hợp lệ các trường còn lại. 4: Nhấn nút Đăng ký. 5: Kiểm tra kết quả sau khi nhấn Đăng ký. | D20: Hệ thống không tạo tài khoản và hiển thị yêu cầu nhập tên đăng nhập. | G20: TCRegister7 | H20: 46218 | I20: Pass | J20: Hệ thống không tạo tài khoản và hiển thị yêu cầu nhập tên đăng nhập.
A21: TC-REGISTER-008 | B21: Kiểm tra đăng ký khi bỏ trống mật khẩu | C21: 1: Mở trang đăng ký. 2: Để trống trường Mật khẩu. 3: Nhập hợp lệ các trường còn lại. 4: Nhấn nút Đăng ký. 5: Kiểm tra kết quả sau khi nhấn Đăng ký. | D21: Hệ thống không tạo tài khoản và hiển thị yêu cầu nhập mật khẩu. | G21: TCRegister8 | H21: 46218 | I21: Pass | J21: Hệ thống không tạo tài khoản và hiển thị yêu cầu nhập mật khẩu.
A22: TC-REGISTER-009 | B22: Kiểm tra đăng ký khi bỏ trống xác nhận mật khẩu | C22: 1: Mở trang đăng ký. 2: Để trống trường Xác nhận mật khẩu. 3: Nhập hợp lệ các trường còn lại. 4: Nhấn nút Đăng ký. 5: Kiểm tra kết quả sau khi nhấn Đăng ký. | D22: Hệ thống không tạo tài khoản và hiển thị yêu cầu nhập xác nhận mật khẩu. | G22: TCRegister9 | H22: 46218 | I22: Pass | J22: Hệ thống không tạo tài khoản và hiển thị yêu cầu nhập xác nhận mật khẩu.
A23: 3. Kiểm tra định dạng dữ liệu
A24: TC-REGISTER-010 | B24: Kiểm tra đăng ký với email sai định dạng | C24: 1: Mở trang đăng ký. 2: Nhập email sai định dạng. 3: Nhập hợp lệ các trường còn lại. 4: Nhấn nút Đăng ký. 5: Kiểm tra kết quả sau khi nhấn Đăng ký. | D24: Hệ thống không tạo tài khoản và hiển thị thông báo email không hợp lệ. | G24: TCRegister10 | H24: 46218 | I24: Pass | J24: Hệ thống không cho phép đăng ký khi email không đúng định dạng và hiển thị thông báo yêu cầu nhập địa chỉ email hợp lệ.
A25: TC-REGISTER-011 | B25: Kiểm tra đăng ký với số điện thoại sai định dạng | C25: 1: Mở trang đăng ký. 2: Nhập số điện thoại 11 chữ số. 3: Nhập hợp lệ các trường còn lại. 4: Nhấn nút Đăng ký. 5: Kiểm tra kết quả sau khi nhấn Đăng ký. | D25: Hệ thống không tạo tài khoản và hiển thị thông báo số điện thoại không hợp lệ. | G25: TCRegister11_1, TCRegister11_2 | H25: 46218 | I25: Fail | J25: Hệ thống vẫn cho phép đăng ký với số điện thoại 11 chữ số và chuyển đến trang đăng nhập, không hiển thị thông báo số điện thoại không hợp lệ. | K25: 46219 | L25: Pass | M25: TCRegisterRetest11
A26: TC-REGISTER-012 | B26: Kiểm tra đăng ký khi xác nhận mật khẩu không khớp | C26: 1: Mở trang đăng ký. 2: Nhập mật khẩu hợp lệ và xác nhận mật khẩu không khớp. 3: Nhập hợp lệ các trường còn lại. 4: Nhấn nút Đăng ký. 5: Kiểm tra kết quả sau khi nhấn Đăng ký. | D26: Hệ thống không tạo tài khoản và hiển thị thông báo xác nhận mật khẩu không khớp. | G26: TCRegister12 | H26: 46218 | I26: Pass | J26: Hệ thống không cho phép đăng ký khi xác nhận mật khẩu không khớp với mật khẩu và hiển thị thông báo.
A27: TC-REGISTER-013 | B27: Kiểm tra đăng ký với mật khẩu ngắn hơn 7 ký tự | C27: 1: Mở trang đăng ký. 2: Nhập mật khẩu ngắn hơn 7 ký tự 3: Nhập xác nhận mật khẩu trùng khớp. 4: Nhập hợp lệ các trường còn lại. 5: Nhấn nút Đăng ký. 6: Kiểm tra kết quả sau khi nhấn Đăng ký. | D27: Hệ thống không tạo tài khoản và hiển thị thông báo mật khẩu không hợp lệ. | G27: TCRegister13_1, TCRegister13_2 | H27: 46218 | I27: Fail | J27: Hệ thống vẫn cho phép đăng ký với mật khẩu chỉ có 6 ký tự và chuyển đến trang đăng nhập, không hiển thị thông báo mật khẩu không hợp lệ. | K27: 46219 | L27: Pass | M27: TCRegisterRetest13
A28: TC-REGISTER-014 | B28: Kiểm tra đăng ký với mật khẩu không có chữ in hoa | C28: 1: Mở trang đăng ký. 2: Nhập mật khẩu không có chữ in hoa, có số, có chữ thường và ký tự đặc biệt 3: Nhập xác nhận mật khẩu trùng khớp. 4: Nhập hợp lệ các trường còn lại. 5: Nhấn nút Đăng ký. 6: Kiểm tra kết quả sau khi nhấn Đăng ký. | D28: Hệ thống không tạo tài khoản và hiển thị thông báo mật khẩu phải chứa ít nhất một chữ in hoa. | G28: TCRegister14_1,TCRegister14_2 | H28: 46218 | I28: Fail | J28: Hệ thống vẫn cho phép đăng ký với mật khẩu không có ký tự hoa và chuyển đến trang đăng nhập, không hiển thị thông báo mật khẩu không hợp lệ. | K28: 46219 | L28: Pass | M28: TCRegisterRetest14
A29: TC-REGISTER-015 | B29: Kiểm tra đăng ký với mật khẩu không có chữ thường | C29: 1: Mở trang đăng ký. 2: Nhập mật khẩu không có chữ thường, có số, có chữ hoa và ký tự đặc biệt 3: Nhập xác nhận mật khẩu trùng khớp. 4: Nhập hợp lệ các trường còn lại. 5: Nhấn nút Đăng ký. 6: Kiểm tra kết quả sau khi nhấn Đăng ký. | D29: Hệ thống không tạo tài khoản và hiển thị thông báo mật khẩu phải chứa ít nhất một chữ thường. | G29: TCRegister15_1, TCRegister15_2 | H29: 46218 | I29: Fail | J29: Hệ thống vẫn cho phép đăng ký với mật khẩu không có chữ thường và chuyển đến trang đăng nhập, không hiển thị thông báo mật khẩu không hợp lệ. | K29: 46219 | L29: Pass | M29: TCRegisterRetest15
A30: TC-REGISTER-016 | B30: Kiểm tra đăng ký với mật khẩu không có chữ số | C30: 1: Mở trang đăng ký. 2: Nhập mật khẩu không có số, có chữ thường, có chữ hoa và ký tự đặc biệt 3: Nhập xác nhận mật khẩu trùng khớp. 4: Nhập hợp lệ các trường còn lại. 5: Nhấn nút Đăng ký. 6: Kiểm tra kết quả sau khi nhấn Đăng ký. | D30: Hệ thống không tạo tài khoản và hiển thị thông báo mật khẩu phải chứa ít nhất một chữ số. | G30: TCRegister16_1, TCRegister16_2 | H30: 46218 | I30: Fail | J30: Hệ thống vẫn cho phép đăng ký với mật khẩu không có chữ số và chuyển đến trang đăng nhập, không hiển thị thông báo mật khẩu không hợp lệ. | K30: 46219 | L30: Pass | M30: TCRegisterRetest16
A31: TC-REGISTER-017 | B31: Kiểm tra đăng ký với mật khẩu không có ký tự đặc biệt | C31: 1: Mở trang đăng ký. 2: Nhập mật khẩu không có ký tự đặc biệt, có số, có chữ thường, có chữ hoa 3: Nhập xác nhận mật khẩu trùng khớp. 4: Nhập hợp lệ các trường còn lại. 5: Nhấn nút Đăng ký. 6: Kiểm tra kết quả sau khi nhấn Đăng ký. | D31: Hệ thống không tạo tài khoản và hiển thị thông báo mật khẩu phải chứa ít nhất một ký tự đặc biệt. | G31: TCRegister17_1,TCRegister17_2 | H31: 46218 | I31: Fail | J31: Hệ thống vẫn cho phép đăng ký với mật khẩu không có ký tự đặc biệt và chuyển đến trang đăng nhập, không hiển thị thông báo mật khẩu không hợp lệ. | K31: 46219 | L31: Pass | M31: TCRegisterRetest17
A32: 4. Kiểm tra dữ liệu đã tồn tại
A33: TC-REGISTER-018 | B33: Kiểm tra đăng ký với tên đăng nhập đã tồn tại | C33: 1: Mở trang đăng ký. 2: Nhập tên đăng nhập là patient_an đã có trong hệ thống. 3: Nhập hợp lệ các trường còn lại. 4: Nhấn nút Đăng ký. 5: Kiểm tra kết quả sau khi nhấn Đăng ký. | D33: Hệ thống không tạo tài khoản và hiển thị thông báo tên đăng nhập đã tồn tại. | G33: TCRegister18_1, TCRegister18_2 | H33: 46218 | I33: Fail | J33: Hệ thống chưa hiển thị thông báo cụ thể khi người dùng đăng ký bằng tên đăng nhập đã tồn tại. | K33: 46219 | L33: Pass | M33: TCRegisterRetest18
A34: TC-REGISTER-019 | B34: Kiểm tra đăng ký với email đã tồn tại | C34: 1: Mở trang đăng ký. 2: Nhập email là an@gmail.com đã có trong hệ thống. 3: Nhập hợp lệ các trường còn lại. 4: Nhấn nút Đăng ký. 5: Kiểm tra kết quả sau khi nhấn Đăng ký. | D34: Hệ thống không tạo tài khoản và hiển thị thông báo email đã tồn tại. | G34: TCRegister19_1, TCRegister19_2 | H34: 46218 | I34: Fail | J34: Hệ thống vẫn cho phép đăng ký tài khoản với email đã tồn tại | K34: 46219 | L34: Pass | M34: TCRegisterRetest19

Sheet BOOKING
A1: TEST CASE
A3: System Name： | B3: SpringMediCareWeb
A4: Module Code： | B4: BOOKING - Appointment Booking
A5: Test requirement: | B5: Appointment Booking
A6: Pass | B6: 7 | C6: Pending | D6: 0
A7: Fail | B7: 2 | C7: Number of test cases: | D7: 9
A9: ID | B9: Test Case Description | C9: Test Case Procedure | D9: Expected Results | G9: Actual Results | H9: Test date | I9: Status | J9: Note | K9: Retest Date | L9: Retest Status | M9: Retest Evidence
A12: 1. Kiểm tra hiển thị thông tin đặt lịch
A13: TC-BOOKING-001 | B13: Đặt lịch thành công với ngày và giờ hợp lệ | C13: 1: Đăng nhập bằng tài khoản Patient hợp lệ. 2: Mở trang Bác sĩ và chọn bác sĩ cần đặt lịch. 3: Mở trang Đặt lịch và kiểm tra đúng thông tin bác sĩ đã chọn. 4: Chọn ngày và giờ hợp lệ, còn trống trong lịch làm việc của bác sĩ. 5: Nhập ghi chú hợp lệ và nhấn Đặt lịch. 6: Kiểm tra thông báo thành công và lịch hẹn vừa được tạo. | D13: Hệ thống tạo lịch hẹn thành công, hiển thị thông báo đặt lịch thành công và giờ vừa đặt xuất hiện trong danh sách giờ đã được đặt | G13: TCBooking1_1, TCBooking1_2 | H13: 46226 | I13: Pass | J13: Chức năng hoạt động đúng, có thông báo đặt lịch thành công
A14: 2. Kiểm tra dữ liệu để trống
A15: TC-BOOKING-002 | B15: Kiểm tra không thể đặt lịch khi chưa chọn ngày khám. | C15: 1: Đăng nhập bằng tài khoản Patient hợp lệ. 2: Mở trang Đặt lịch của bác sĩ cần đặt. 3: Để trống ngày khám. 4: Chọn giờ khám và nhập ghi chú hợp lệ. 5: Nhấn Đặt lịch. 6: Kiểm tra thông báo validation và xác nhận lịch hẹn không được tạo. | D15: Hệ thống yêu cầu người dùng chọn ngày khám và không tạo lịch hẹn | G15: TCBooking2 | H15: 46226 | I15: Pass | J15: Hệ thống hoạt động đúng, có thông báo yêu cầu nhập ngày khám
A16: TC-BOOKING-003 | B16: Kiểm tra không thể đặt lịch khi chưa chọn giờ khám. | C16: 1: Đăng nhập bằng tài khoản Patient hợp lệ. 2: Mở trang Đặt lịch của bác sĩ cần đặt. 3: Chọn một ngày bác sĩ có lịch làm việc. 4: Để trống giờ khám và nhập ghi chú hợp lệ. 5: Nhấn Đặt lịch. 6: Kiểm tra thông báo validation và xác nhận lịch hẹn không được tạo. | D16: Hệ thống yêu cầu người dùng nhập giờ khám và không tạo lịch hẹn | G16: TCBooking3 | H16: 46226 | I16: Pass | J16: Hệ thống hoạt động đúng, có thông báo yêu cầu nhập giờ khám
A17: TC-BOOKING-004 | B17: Kiểm tra đặt lịch khi không nhập ghi chú. | C17: 1: Đăng nhập bằng tài khoản Patient hợp lệ. 2: Mở trang Đặt lịch của bác sĩ cần đặt. 3: Chọn ngày và giờ hợp lệ, còn trống trong lịch làm việc của bác sĩ. 4: Để trống trường ghi chú. 5: Nhấn Đặt lịch. 6: Kiểm tra kết quả đặt lịch. | D17: Hệ thống vẫn tạo lịch hẹn thành công vì ghi chú là thông tin không bắt buộc | G17: TCBooking4_1, TCBooking4_2 | H17: 46226 | I17: Pass | J17: Hệ thống hoạt động đúng, vì ghi chú không phải trường bắt buộc
A18: 3. Kiểm tra ngày và giờ không hợp lệ
A19: TC-BOOKING-005 | B19: Kiểm tra không thể đặt lịch vào ngày bác sĩ không có lịch làm việc. | C19: 1: Đăng nhập bằng tài khoản Patient hợp lệ. 2: Mở trang Đặt lịch của bác sĩ cần đặt. 3: Chọn một ngày bác sĩ không có lịch làm việc. 4: Kiểm tra trạng thái thời gian đặt lịch của ngày đã chọn. 5: Thực hiện đặt lịch nếu hệ thống cho phép thao tác. 6: Kiểm tra lịch hẹn không được tạo. | D19: Hệ thống không cho phép Patient đặt lịch vào ngày bác sĩ không làm việc và không tạo lịch hẹn mới. | G19: TCBooking5 | H19: 46226 | I19: Pass | J19: Hệ thống hoạt động đúng, có hiện thông báo đặt lịch thất bại.
A20: TC-BOOKING-006 | B20: Kiểm tra không thể đặt lịch vào giờ nằm ngoài ca làm việc của bác sĩ. | C20: 1: Đăng nhập bằng tài khoản Patient hợp lệ. 2: Mở trang Đặt lịch của bác sĩ cần đặt. 3: Chọn một ngày bác sĩ có lịch làm việc. 4: Chọn hoặc nhập giờ nằm ngoài ca làm việc của bác sĩ. 5: Thực hiện đặt lịch. 6: Kiểm tra thông báo và xác nhận lịch hẹn không được tạo. | D20: Hệ thống không tạo lịch hẹn và hiển thị thông báo bác sĩ không làm việc vào thời gian đã chọn | G20: TCBooking6 | H20: 46226 | I20: Pass | J20: Hệ thống hoạt động đúng, có hiện thông báo đặt lịch thất bại.
A21: 4. Kiểm tra xử lý sau khi đăng nhập
A22: TC-BOOKING-007 | B22: Kiểm tra không thể đặt lịch trùng với giờ đã có lịch hẹn. | C22: 1: Đăng nhập bằng tài khoản Patient hợp lệ. 2: Mở trang Đặt lịch của bác sĩ cần đặt. 3: Xác định ngày và giờ đã có lịch hẹn của bác sĩ. 4: Chọn lại đúng ngày và giờ đã có lịch hẹn. 5: Nhấn Đặt lịch. 6: Kiểm tra thông báo và xác nhận không phát sinh lịch hẹn trùng. | D22: Hệ thống không tạo lịch hẹn mới và hiển thị thông báo giờ đã có người đặt | G22: TCBooking7 | H22: 46226 | I22: Pass | J22: Hệ thống hoạt động đúng, có hiện thông báo đặt lịch thất bại.
A23: TC-BOOKING-008 | B23: Kiểm tra không thể đặt lịch cách một lịch hẹn hiện có dưới 30 phút. | C23: 1: Đăng nhập bằng tài khoản Patient hợp lệ. 2: Xác định một lịch hẹn đã tồn tại của bác sĩ. 3: Mở trang Đặt lịch của cùng bác sĩ. 4: Chọn cùng ngày và một giờ cách lịch hẹn hiện có dưới 30 phút. 5: Nhấn Đặt lịch. 6: Kiểm tra thông báo và xác nhận lịch hẹn mới không được tạo. | D23: Hệ thống từ chối thời gian cách lịch hẹn hiện có dưới 30 phút và không tạo lịch hẹn mới. | G23: TCBooking8 | H23: 46226 | I23: Fail | J23: Phát hiện lỗi, cần giới hạn khoảng cách tối thiểu 30 phút giữa các lịch hẹn. | K23: 46226 | L23: Pass | M23: TCBookingRetest8
A24: 5. Kiểm tra quyền truy cập chức năng đặt lịch
A25: TC-BOOKING-009 | B25: Kiểm tra người dùng chưa đăng nhập không được truy cập chức năng Đặt lịch hẹn. | C25: 1: Đảm bảo người dùng đang ở trạng thái chưa đăng nhập. 2: Mở trang Bác sĩ. 3: Chọn bác sĩ cần đặt lịch. 4: Nhấn nút Đặt lịch hẹn. 5: Kiểm tra trang được điều hướng đến. 6: Xác nhận Guest không thể truy cập form Đặt lịch. | D25: Hệ thống không cho phép người dùng chưa đăng nhập truy cập form Đặt lịch và yêu cầu đăng nhập trước khi tiếp tục. Không có lịch hẹn nào được tạo. | G25: TCBooking9_1, TCBooking9_2 | H25: 46252 | I25: Fail | J25: Guest chưa đăng nhập vẫn truy cập được trang đặt lịch. Cần bổ sung kiểm tra xác thực trước khi cho phép truy cập chức năng đặt lịch.
A26: TC-BOOKING-010 | B26: Kiểm tra test case mới của chức năng Đặt lịch được thực thi thành công trên Local và GitHub Actions. | C26: 1: Đăng nhập bằng tài khoản Patient hợp lệ. 2: Mở trang Bác sĩ và chọn bác sĩ cần đặt lịch. 3: Mở trang Đặt lịch và kiểm tra các trường cần thiết. 4: Chọn ngày và giờ hợp lệ, còn trống trong lịch làm việc của bác sĩ. 5: Nhập ghi chú hợp lệ và nhấn Đặt lịch. 6: Kiểm tra thông báo thành công và lịch hẹn vừa được tạo với trạng thái pending. 7: Chạy TC-BOOKING-010 trên môi trường Local và ghi nhận kết quả. 8: Push source code lên branch CI và kiểm tra GitHub Actions tự động thực thi lại bộ test. 9: Đối chiếu số lượng test case trước và sau khi bổ sung TC-BOOKING-010. | D26: TC-BOOKING-010 thực thi PASS trên Local. Sau khi source code được push lên branch CI, GitHub Actions tự động chạy lại bộ kiểm thử, nhận diện TC-BOOKING-010 và tổng số test case tăng từ 125 lên 126. TC-BOOKING-010 tiếp tục PASS trên môi trường CI. | G26: TCBooking10_1, TCBooking10_2 | H26: 46279 | I26: Pass | J26: TC-BOOKING-010 PASS trên Local. Full suite tăng từ 125 lên 126 test case và đạt 121 PASS, 5 XFAIL. Sau khi push lên branch CI, GitHub Actions tự động chạy lại và thu thập 126 test case.

Sheet APPOINTMENT
A1: TEST CASE
A3: System Name： | B3: SpringMediCareWeb
A4: Module Code： | B4: APPOINTMENT - Appointment Management
A5: Test requirement: | B5: Appointment Management and Examination
A6: Pass | B6: 5 | C6: Pending | D6: 0
A7: Fail | B7: 4 | C7: Number of test cases: | D7: 9
A9: ID | B9: Test Case Description | C9: Test Case Procedure | D9: Expected Results | G9: Actual Results | H9: Test date | I9: Status | J9: Note | K9: Retest Date | L9: Retest Status | M9: Retest Evidence
A12: 1. Kiểm tra lịch được chuyển đến Admin
A13: TC-APPOINTMENT-001 | B13: Kiểm tra lịch hẹn bệnh nhân vừa đặt được hiển thị đúng trên trang Quản lý lịch hẹn của Admin. | C13: 1: Đăng nhập bằng tài khoản bệnh nhân và mở trang đặt lịch của bác sĩ có lịch làm việc. 2: Chọn ngày, giờ hợp lệ và nhập ghi chú TC-APPOINTMENT-001. 3: Nhấn Đặt lịch và kiểm tra đặt lịch thành công. 4: Đăng xuất và đăng nhập bằng tài khoản Admin. 5: Mở trang Quản lý lịch hẹn và tìm lịch vừa tạo. 6: Kiểm tra thông tin và trạng thái của lịch. | D13: Lịch được tạo thành công và hiển thị cho Admin với đúng bệnh nhân, bác sĩ, ngày giờ, ghi chú; trạng thái Chờ xác nhận và có nút Xác nhận, Hủy. | G13: TCAppointment1_1, TCAppointment1_2, TCAppointment1_3 | H13: 46232 | I13: Pass | J13: Lịch hẹn sau khi bệnh nhân đặt được gửi đến Admin đầy đủ và đúng trạng thái Chờ xác nhận.
A14: 2. Kiểm tra Admin quản lý lịch
A15: TC-APPOINTMENT-002 | B15: Kiểm tra Admin xác nhận thành công lịch hẹn đang ở trạng thái Chờ xác nhận. | C15: 1: Đăng nhập Admin và mở trang Quản lý lịch hẹn. 2: Tìm lịch TC-APPOINTMENT-002 đang ở trạng thái Chờ xác nhận. 3: Nhấn Xác nhận và đồng ý trên hộp thoại xác nhận. 4: Kiểm tra thông báo xác nhận thành công. 5: Kiểm tra trạng thái và thông tin lịch sau khi xác nhận. | D15: Trạng thái chuyển sang Đã xác nhận; nút Xác nhận, Hủy không còn hiển thị; thông tin lịch không thay đổi. | G15: TCAppointment2_1, TCAppointment2_2 | H15: 46232 | I15: Pass | J15: Admin xác nhận lịch thành công, trạng thái chuyển sang Đã xác nhận và thông tin lịch không thay đổi.
A16: TC-APPOINTMENT-003 | B16: Kiểm tra Admin hủy thành công lịch hẹn đang chờ xác nhận. | C16: 1: Đăng nhập Admin và mở trang Quản lý lịch hẹn. 2: Tìm lịch TC-APPOINTMENT-003 đang ở trạng thái Chờ xác nhận. 3: Nhấn Hủy và đồng ý trên hộp thoại xác nhận. 4: Kiểm tra thông báo hủy lịch thành công. 5: Kiểm tra trạng thái và thông tin lịch sau khi hủy. | D16: Trạng thái chuyển sang Đã hủy; nút Xác nhận, Hủy không còn hiển thị; thông tin lịch không thay đổi. | G16: TCAppointment3_1, TCAppointment3_2, TCAppointment3_3 | H16: 46232 | I16: Pass | J16: Admin hủy lịch thành công, trạng thái chuyển sang Đã hủy và các nút thao tác không còn hiển thị.
A17: 3. Kiểm tra quyền bác sĩ theo trạng thái lịch
A18: TC-APPOINTMENT-004 | B18: Kiểm tra quyền xem hồ sơ bệnh nhân của bác sĩ khi lịch đang chờ xác nhận. | C18: 1: Đăng nhập bằng đúng tài khoản bác sĩ của lịch. 2: Mở trang Lịch hẹn bệnh nhân và tìm lịch TC-APPOINTMENT-004. 3: Kiểm tra trạng thái và các nút thao tác của lịch. 4: Nhấn Xem hồ sơ. 5: Kiểm tra hồ sơ/lịch sử khám của bệnh nhân. | D18: Lịch ở trạng thái Chờ xác nhận; bác sĩ được xem hồ sơ/lịch sử khám nhưng không có nút Khám bệnh và không thể tạo hồ sơ bệnh án mới. | G18: TCAppointment4 | H18: 46232 | I18: Fail | J18: Bác sĩ không thể xem hồ sơ bệnh nhân khi lịch đang chờ xác nhận, không đúng với yêu cầu nghiệp vụ.
A19: TC-APPOINTMENT-005 | B19: Kiểm tra bác sĩ không thể truy cập trực tiếp trang khám của lịch chưa được Admin xác nhận. | C19: 1: Đăng nhập bằng đúng tài khoản bác sĩ của lịch TC-APPOINTMENT-005. 2: Truy cập trực tiếp URL trang khám bằng appointmentId của lịch. 3: Kiểm tra phản hồi của hệ thống. 4: Kiểm tra không thể thực hiện và lưu thông tin khám. 5: Kiểm tra trạng thái lịch và dữ liệu hồ sơ. | D19: Trang khám bị chặn, chuyển hướng hoặc thông báo lịch chưa được xác nhận; không tạo hồ sơ bệnh án; lịch vẫn ở trạng thái Chờ xác nhận. | G19: TCAppointment5_1, TCAppointment5_2 | H19: 46232 | I19: Fail | J19: Hệ thống chỉ ẩn nút Khám bệnh trên giao diện nhưng chưa chặn truy cập trực tiếp đối với lịch chưa được Admin xác nhận. | K19: 46233 | L19: Pass | M19: TCAppointmentRetest5
A20: TC-APPOINTMENT-006 | B20: Kiểm tra đúng bác sĩ được phép khám bệnh khi lịch đã được xác nhận. | C20: 1: Đăng nhập bằng đúng tài khoản bác sĩ của lịch. 2: Mở trang Lịch hẹn bệnh nhân và tìm lịch TC-APPOINTMENT-006. 3: Kiểm tra lịch ở trạng thái Đã xác nhận và có nút Khám bệnh. 4: Nhấn Khám bệnh. 5: Kiểm tra thông tin bệnh nhân và form khám được hiển thị. | D20: Trang khám mở đúng lịch và bệnh nhân; hiển thị form nhập chẩn đoán, hướng điều trị; lịch vẫn Đã xác nhận khi chưa lưu hồ sơ. | G20: TCAppointment6_1, TCAppointment6_2 | H20: 46232 | I20: Pass | J20: Lịch đã xác nhận hiển thị nút Khám bệnh và mở đúng thông tin bệnh nhân cùng form khám.
A21: TC-APPOINTMENT-007 | B21: Kiểm tra bác sĩ khác không thể khám lịch hẹn không thuộc mình. | C21: 1: Đăng nhập bằng tài khoản bác sĩ khác với bác sĩ của lịch TC-APPOINTMENT-007. 2: Mở trang Lịch hẹn bệnh nhân và kiểm tra lịch không xuất hiện. 3: Truy cập trực tiếp URL trang khám bằng appointmentId của lịch. 4: Kiểm tra phản hồi của hệ thống. 5: Kiểm tra trạng thái lịch và dữ liệu hồ sơ. | D21: Lịch không xuất hiện trong danh sách; truy cập trực tiếp bị chặn/chuyển hướng hoặc báo không có quyền; không tạo hồ sơ bệnh án và trạng thái lịch không thay đổi. | G21: TCAppointment7_1, TCAppointment7_2 | H21: 46232 | I21: Fail | J21: Hệ thống chưa kiểm tra lịch hẹn có thuộc bác sĩ đang đăng nhập hay không. | K21: 46233 | L21: Pass | M21: TCAppointmentRetest7
A22: TC-APPOINTMENT-008 | B22: Kiểm tra bác sĩ không thể khám bệnh đối với lịch đã bị hủy. | C22: 1: Đăng nhập bằng đúng tài khoản bác sĩ của lịch. 2: Mở trang Lịch hẹn bệnh nhân và tìm lịch TC-APPOINTMENT-008. 3: Kiểm tra lịch ở trạng thái Đã hủy và không có nút Khám bệnh. 4: Truy cập trực tiếp URL trang khám bằng appointmentId của lịch. 5: Kiểm tra phản hồi và dữ liệu của lịch. | D22: Không có nút Khám bệnh; truy cập trực tiếp trang khám bị chặn/chuyển hướng; không tạo hồ sơ bệnh án; trạng thái vẫn Đã hủy. | G22: TCAppointment8_1, TCAppointment8_2 | H22: 46232 | I22: Fail | J22: Hệ thống chưa chặn truy cập trực tiếp trang khám đối với lịch đã bị hủy | K22: 46233 | L22: Pass | M22: TCAppointmentRetest8
A23: 4. Kiểm tra bác sĩ hoàn thành khám
A24: TC-APPOINTMENT-009 | B24: Kiểm tra bác sĩ lưu hồ sơ bệnh án và hoàn thành lịch hẹn đã xác nhận. | C24: 1: Đăng nhập bằng đúng tài khoản bác sĩ và mở lịch TC-APPOINTMENT-009 đã được xác nhận. 2: Nhấn Khám bệnh. 3: Nhập chẩn đoán và hướng điều trị hợp lệ. 4: Nhấn Lưu hồ sơ và kiểm tra lưu thành công. 5: Quay lại danh sách lịch hẹn và kiểm tra trạng thái. 6: Mở lại hồ sơ và kiểm tra thông tin vừa lưu. | D24: Hồ sơ bệnh án được lưu đúng bệnh nhân, bác sĩ và lịch hẹn; trạng thái chuyển sang Đã hoàn thành; không còn nút Khám bệnh và có thể xem lại hồ sơ. | G24: TCAppointment9_1, TCAppointment9_2, TCAppointment9_3 | H24: 46232 | I24: Pass | J24: Hồ sơ bệnh án được lưu thành công, lịch chuyển sang Đã hoàn thành và hiển thị nút Xem hồ sơ.

Sheet MEDICAL
A1: TEST CASE
A3: System Name： | B3: SpringMediCareWeb
A4: Module Code： | B4: MEDICAL - Medical Record Management
A5: Test requirement: | B5: Medical Record Management
A6: Pass | B6: 7 | C6: Pending | D6: 0
A7: Fail | B7: 2 | C7: Number of test cases: | D7: 9
A9: ID | B9: Test Case Description | C9: Test Case Procedure | D9: Expected Results | G9: Actual Results | H9: Test date | I9: Status | J9: Note | K9: Retest Date | L9: Retest Status | M9: Retest Evidence
A12: 1. Kiểm tra tạo hồ sơ bệnh án
A13: TC-MEDICAL-001 | B13: Kiểm tra bác sĩ có thể tạo hồ sơ bệnh án thành công cho lịch hẹn đã được xác nhận. | C13: 1: Chuẩn bị một lịch hẹn Đã xác nhận và chưa có hồ sơ bệnh án. 2: Đăng nhập bằng bác sĩ phụ trách lịch hẹn. 3: Mở trang Lịch hẹn bệnh nhân và tìm đúng lịch đã chuẩn bị. 4: Kiểm tra lịch ở trạng thái Đã xác nhận và có nút Khám bệnh. 5: Nhấn Khám bệnh. 6: Kiểm tra trang Khám bệnh được mở đúng cho lịch hẹn. 7: Nhập Chẩn đoán và Hướng điều trị hợp lệ. 8: Nhấn Lưu hồ sơ bệnh án. 9: Kiểm tra hồ sơ được tạo đúng và lịch chuyển sang Đã hoàn thành. | D13: Hệ thống tạo hồ sơ bệnh án thành công. Hồ sơ được gắn đúng với lịch hẹn, bệnh nhân và bác sĩ. Chẩn đoán và hướng điều trị được lưu chính xác. Trạng thái lịch chuyển từ Đã xác nhận sang Đã hoàn thành. Nút Khám bệnh được thay bằng nút Xem hồ sơ. | G13: TCMedical1_1, TCMedical1_2, TCMedical1_3 | H13: 46233 | I13: Pass | J13: Bác sĩ tạo hồ sơ bệnh án thành công, dữ liệu được lưu đúng và lịch hẹn chuyển sang trạng thái Đã hoàn thành.
A14: TC-MEDICAL-002 | B14: Kiểm tra hệ thống không cho phép bác sĩ tạo hồ sơ bệnh án khi bỏ trống Chẩn đoán. | C14: 1: Chuẩn bị lịch hẹn Đã xác nhận và chưa có hồ sơ bệnh án. 2: Đăng nhập bằng bác sĩ phụ trách. 3: Mở trang Khám bệnh của lịch đã chuẩn bị. 4: Để trống Chẩn đoán và nhập Hướng điều trị hợp lệ. 5: Nhấn Lưu hồ sơ bệnh án. 6: Kiểm tra thông báo validation. 7: Kiểm tra hồ sơ không được tạo và lịch vẫn Đã xác nhận. | D14: Hệ thống hiển thị thông báo yêu cầu nhập đầy đủ chẩn đoán. Không tạo hồ sơ bệnh án mới. Trạng thái lịch vẫn là Đã xác nhận. Dữ liệu hướng điều trị chưa được lưu. | G14: TCMedical2_1, TCMedical2_2, TCMedical2_3 | H14: 46233 | I14: Pass | J14: Hệ thống hiển thị cảnh báo khi bỏ trống chẩn đoán, không tạo hồ sơ bệnh án và giữ nguyên trạng thái
A15: TC-MEDICAL-003 | B15: Kiểm tra hệ thống không cho phép bác sĩ tạo hồ sơ bệnh án khi bỏ trống Hướng điều trị. | C15: 1: Chuẩn bị lịch hẹn Đã xác nhận và chưa có hồ sơ bệnh án. 2: Đăng nhập bằng bác sĩ phụ trách. 3: Mở trang Khám bệnh của lịch đã chuẩn bị. 4: Nhập Chẩn đoán hợp lệ và để trống Hướng điều trị. 5: Nhấn Lưu hồ sơ bệnh án. 6: Kiểm tra thông báo validation. 7: Kiểm tra hồ sơ không được tạo và lịch vẫn Đã xác nhận. | D15: Hệ thống hiển thị thông báo yêu cầu nhập đầy đủ hướng điều trị. Không tạo hồ sơ bệnh án mới. Trạng thái lịch vẫn là Đã xác nhận. Dữ liệu chẩn đoán chưa được lưu. | G15: TCMedical3_1, TCMedical3_2, TCMedical3_3 | H15: 46233 | I15: Pass | J15: Hệ thống hiển thị cảnh báo khi bỏ trống hướng điều trị, không tạo hồ sơ bệnh án và giữ nguyên trạng thái Đã xác nhận.
A16: TC-MEDICAL-004 | B16: Kiểm tra hệ thống không cho phép bác sĩ tạo thêm hồ sơ bệnh án cho lịch hẹn đã hoàn thành và đã có hồ sơ bệnh án. | C16: 1: Chuẩn bị lịch hẹn Đã hoàn thành và đã có hồ sơ bệnh án. 2: Đăng nhập bằng bác sĩ phụ trách. 3: Mở trang Lịch hẹn bệnh nhân và tìm đúng lịch đã chuẩn bị. 4: Kiểm tra lịch ở trạng thái Đã hoàn thành, có nút Xem hồ sơ và không còn nút Khám bệnh. 5: Nhấn Xem hồ sơ và kiểm tra hồ sơ hiện có được hiển thị đúng. 6: Truy cập trực tiếp trang Khám bệnh bằng appointmentId của lịch đã hoàn thành. 7: Kiểm tra hệ thống chặn thao tác khám bệnh và không hiển thị form tạo hồ sơ mới. 8: Mở lại hồ sơ và kiểm tra dữ liệu cũ không thay đổi. | D16: Bác sĩ xem được hồ sơ bệnh án hiện có. Khi truy cập trực tiếp trang Khám bệnh của lịch đã hoàn thành, hệ thống chặn truy cập và không hiển thị form tạo hồ sơ mới. Hồ sơ cũ không bị thay đổi và lịch vẫn ở trạng thái Đã hoàn thành. | G16: TCMedical4_1, TCMedical4_2 | H16: 46233 | I16: Pass | J16: Hệ thống cho phép xem hồ sơ hiện có nhưng chặn mở lại trang Khám bệnh để tạo hồ sơ bệnh án thứ hai.
A17: 2. Kiểm tra xem hồ sơ bệnh án
A18: TC-MEDICAL-005 | B18: Kiểm tra bác sĩ có thể xem đúng hồ sơ bệnh án của lịch hẹn đã hoàn thành. | C18: 1: Chuẩn bị lịch Đã hoàn thành và đã có hồ sơ bệnh án. 2: Đăng nhập bằng bác sĩ phụ trách. 3: Mở trang Lịch hẹn bệnh nhân và tìm đúng lịch. 4: Kiểm tra lịch có nút Xem hồ sơ. 5: Nhấn Xem hồ sơ. 6: Kiểm tra appointmentId, bệnh nhân và bác sĩ phụ trách. 7: Kiểm tra Chẩn đoán và Hướng điều trị khớp dữ liệu đã lưu. 8: Kiểm tra thao tác xem hồ sơ không làm thay đổi dữ liệu hoặc trạng thái lịch. | D18: Hệ thống mở đúng hồ sơ bệnh án của lịch hẹn. Hiển thị đúng bệnh nhân và bác sĩ phụ trách. Hiển thị đúng chẩn đoán và hướng điều trị đã lưu. Hồ sơ được gắn đúng với appointmentId. Không làm thay đổi trạng thái hoặc dữ liệu hồ sơ. | G18: TCMedical5_1, TCMedical5_2 | H18: 46233 | I18: Pass | J18: Hệ thống mở đúng hồ sơ bệnh án của lịch đã hoàn thành và hiển thị đầy đủ, chính xác thông tin đã lưu.
A19: 3. Kiểm tra cập nhật hồ sơ bệnh án
A20: TC-MEDICAL-006 | B20: Kiểm tra bác sĩ có thể cập nhật thành công hồ sơ bệnh án thuộc lịch hẹn của mình. | C20: 1: Chuẩn bị lịch Đã hoàn thành, đã có hồ sơ và ghi nhận dữ liệu hiện tại. 2: Đăng nhập bằng bác sĩ phụ trách và mở hồ sơ. 3: Nhấn Cập nhật hồ sơ. 4: Kiểm tra form cập nhật hiển thị đúng dữ liệu hiện tại. 5: Thay đổi Chẩn đoán và Hướng điều trị. 6: Nhấn Lưu cập nhật. 7: Kiểm tra thông báo cập nhật thành công. 8: Mở lại hồ sơ và kiểm tra dữ liệu mới. 9: Kiểm tra hồ sơ vẫn thuộc cùng lịch hẹn, bệnh nhân và bác sĩ. 10: Kiểm tra hệ thống cập nhật hồ sơ hiện tại, không tạo thêm hồ sơ mới và lịch vẫn Đã hoàn thành. | D20: Hệ thống cập nhật hồ sơ bệnh án thành công. Nội dung mới được hiển thị chính xác. Hệ thống cập nhật hồ sơ hiện tại, không tạo thêm hồ sơ mới. Hồ sơ vẫn gắn đúng với bệnh nhân, bác sĩ và lịch hẹn. Trạng thái lịch vẫn là Đã hoàn thành. | G20: TCMedical6_1, TCMedical6_2, TCMedical6_3 | H20: 46233 | I20: Pass | J20: Hệ thống cho phép bác sĩ cập nhật hồ sơ bệnh án thành công. Sau khi lưu, thông báo thành công hiển thị và nội dung hồ sơ được cập nhật đúng theo dữ liệu mới.
A21: TC-MEDICAL-007 | B21: Kiểm tra bác sĩ khác không thể xem hồ sơ bệnh án không thuộc lịch hẹn của mình. | C21: 1: Chuẩn bị hồ sơ bệnh án thuộc Doctor A và ghi nhận dữ liệu hiện tại. 2: Đăng nhập bằng Doctor B. 3: Mở trang Lịch hẹn bệnh nhân. 4: Kiểm tra lịch của Doctor A không xuất hiện trong danh sách của Doctor B. 5: Truy cập trực tiếp URL xem hồ sơ của Doctor A. 6: Kiểm tra hệ thống chặn truy cập và không hiển thị dữ liệu hồ sơ. 7: Đăng xuất Doctor B và đăng nhập lại Doctor A. 8: Mở lại hồ sơ và kiểm tra dữ liệu không thay đổi. | D21: Hồ sơ của Doctor A không xuất hiện trong danh sách của Doctor B. Khi Doctor B truy cập trực tiếp URL, hệ thống chặn truy cập hoặc hiển thị thông báo không có quyền. Thông tin bệnh nhân và nội dung hồ sơ không được hiển thị. Dữ liệu hồ sơ không thay đổi. | G21: TCMedical7 | H21: 46233 | I21: Fail | J21: Hệ thống chưa kiểm tra quyền xem hồ sơ, nên bác sĩ Tran Binh vẫn xem được chi tiết hồ sơ thuộc bác sĩ Ly Minh. | K21: 46234 | L21: Pass | M21: TCMedicalRetest7
A22: TC-MEDICAL-008 | B22: Kiểm tra bác sĩ khác không thể cập nhật hồ sơ bệnh án không thuộc lịch hẹn của mình. | C22: 1: Chuẩn bị hồ sơ bệnh án thuộc Doctor A và ghi nhận dữ liệu hiện tại. 2: Đăng nhập bằng Doctor B. 3: Truy cập trực tiếp URL hồ sơ của Doctor A. 4: Kiểm tra hệ thống chặn truy cập và Doctor B không thể sử dụng chức năng Cập nhật hồ sơ. 5: Đăng xuất Doctor B và đăng nhập lại Doctor A. 6: Mở lại hồ sơ đã chuẩn bị. 7: Kiểm tra Chẩn đoán và Hướng điều trị không thay đổi. 8: Kiểm tra hồ sơ vẫn thuộc Doctor A và lịch vẫn Đã hoàn thành. | D22: Hệ thống không cho phép Doctor B cập nhật hồ sơ thuộc Doctor A. Doctor B bị chặn truy cập hoặc không có quyền sử dụng chức năng Cập nhật hồ sơ. Chẩn đoán và hướng điều trị cũ không bị thay đổi. Hồ sơ vẫn thuộc đúng Doctor A. | G22: TCMedical8_1, TCMedical8_2, TCMedical8_3 | H22: 46233 | I22: Fail | J22: Hệ thống chưa kiểm tra quyền sở hữu hồ sơ khi cập nhật. Bác sĩ Tran Binh vẫn mở được chức năng Cập nhật hồ sơ thuộc bác sĩ Ly Minh, thay đổi dữ liệu và lưu thành công. | K22: 46234 | L22: Pass | M22: TCMedicalRetest8
A23: TC-MEDICAL-009 | B23: Kiểm tra thao tác Hủy cập nhật không làm thay đổi dữ liệu hồ sơ bệnh án đã lưu. | C23: 1: Chuẩn bị hồ sơ bệnh án và ghi nhận dữ liệu hiện tại. 2: Đăng nhập bằng bác sĩ phụ trách và mở hồ sơ. 3: Nhấn Cập nhật hồ sơ. 4: Kiểm tra form cập nhật hiển thị đúng dữ liệu hiện tại. 5: Thay đổi Chẩn đoán và Hướng điều trị bằng dữ liệu mới. 6: Nhấn Hủy. 7: Kiểm tra form cập nhật được đóng và dữ liệu mới không được lưu. 8: Mở lại hồ sơ và kiểm tra dữ liệu ban đầu vẫn được giữ nguyên. 9: Kiểm tra hồ sơ vẫn thuộc đúng lịch hẹn, bệnh nhân, bác sĩ và lịch vẫn Đã hoàn thành. | D23: Hệ thống hủy thao tác cập nhật và đóng form chỉnh sửa. Dữ liệu mới nhập không được lưu. Chẩn đoán và hướng điều trị cũ vẫn được giữ nguyên. Hồ sơ vẫn thuộc đúng bệnh nhân, bác sĩ và lịch hẹn. Trạng thái lịch vẫn là Đã hoàn thành. | G23: TCMedical9_1, TCMedical9_2, TCMedical9_3 | H23: 46233 | I23: Pass | J23: Hệ thống hủy thao tác cập nhật thành công, không lưu dữ liệu tạm và giữ nguyên nội dung hồ sơ bệnh án ban đầu.

Sheet DS_ADMIN
A1: TEST CASE
A3: System Name： | B3: SpringMediCareWeb
A4: Module Code： | B4: SCHEDULE - Doctor Schedule Management
A5: Test requirement: | B5: Doctor Schedule Management
A6: Pass | B6: 13 | C6: Pending | D6: 0
A7: Fail | B7: 7 | C7: Number of test cases: | D7: 20
A9: ID | B9: Test Case Description | C9: Test Case Procedure | D9: Expected Results | G9: Actual Results | H9: Test date | I9: Status | J9: Note | K9: Retest Date | L9: Retest Status | M9: Retest Evidence
A12: 1. Kiểm tra hiển thị form Thêm lịch làm việc
A13: TC-DS-ADMIN-001 | B13: Kiểm tra form Thêm lịch làm việc hiển thị đầy đủ thông tin cần thiết. | C13: 1: Đăng nhập với vai trò Admin. 2: Mở trang Quản lý lịch làm việc bác sĩ. 3: Quan sát form Thêm lịch làm việc. 4: Mở danh sách Bác sĩ. 5: Mở danh sách Ca làm việc. 6: Mở danh sách Trạng thái. 7: Kiểm tra các trường, lựa chọn và giá trị mặc định trên form. | D13: Form hiển thị đầy đủ các trường Bác sĩ, Ngày làm việc, Ca làm việc, Trạng thái, Ghi chú và nút Thêm lịch; Bác sĩ mặc định chưa chọn; Ngày làm việc để trống; Ca mặc định là Ca sáng; Trạng thái mặc định là Có lịch làm việc; Ghi chú để trống. | G13: TCDsAdmin1_1, TCDsAdmin1_2, TCDsAdmin1_3 | H13: 46240 | I13: Pass | J13: Giao diện hệ thống hiển thị đúng.
A14: 2. Kiểm tra thêm lịch với dữ liệu hợp lệ
A15: TC-DS-ADMIN-002 | B15: Kiểm tra Admin thêm lịch làm việc cho bác sĩ với dữ liệu hợp lệ. | C15: 1: Đăng nhập với vai trò Admin. 2: Mở trang Quản lý lịch làm việc bác sĩ. 3: Chọn một bác sĩ. 4: Chọn một ngày làm việc chưa có lịch tại ca cần tạo. 5: Chọn Ca sáng. 6: Chọn trạng thái Có lịch làm việc. 7: Nhập ghi chú cho lịch. 8: Nhấn Thêm lịch. 9: Kiểm tra thông báo và lịch vừa tạo trong Danh sách lịch làm việc. | D15: Hệ thống thêm lịch thành công và lịch mới hiển thị đúng bác sĩ, ngày, ca, trạng thái và ghi chú đã nhập. | G15: TCDsAdmin2 | H15: 46240 | I15: Fail | J15: Hệ thống báo lỗi "Có lỗi xảy ra. Kiểm tra lại đăng nhập hoặc dữ liệu nhập." | K15: 46240 | L15: Pass | M15: TCDsAdminRetest2_1, TCDsAdminRetest2_2
A16: TC-DS-ADMIN-003 | B16: Kiểm tra Admin thêm lịch cho bác sĩ với trạng thái Không làm việc. | C16: 1: Đăng nhập với vai trò Admin. 2: Mở trang Quản lý lịch làm việc bác sĩ. 3: Chọn một bác sĩ. 4: Chọn ngày và ca chưa có lịch. 5: Chọn trạng thái Không làm việc. 6: Nhập ghi chú phù hợp. 7: Nhấn Thêm lịch. 8: Kiểm tra thông báo và lịch vừa tạo trong Danh sách lịch làm việc. | D16: Hệ thống thêm lịch thành công với trạng thái Không làm việc và lưu đúng thông tin đã nhập. | G16: TCDsAdmin3 | H16: 46240 | I16: Fail | J16: Hệ thống báo lỗi "Có lỗi xảy ra. Kiểm tra lại đăng nhập hoặc dữ liệu nhập." | K16: 46240 | L16: Pass | M16: TCDsAdminRetest3_1, TCDsAdminRetest3_2
A17: TC-DS-ADMIN-004 | B17: Kiểm tra Admin có thể thêm lịch khi để trống Ghi chú. | C17: 1: Đăng nhập với vai trò Admin. 2: Mở trang Quản lý lịch làm việc bác sĩ. 3: Chọn bác sĩ, ngày làm việc và ca chưa có lịch. 4: Chọn trạng thái Có lịch làm việc. 5: Để trống trường Ghi chú. 6: Nhấn Thêm lịch. 7: Kiểm tra lịch vừa tạo trong Danh sách lịch làm việc. | D17: Hệ thống vẫn thêm lịch thành công và trường Ghi chú của lịch để trống. | G17: TCDsAdmin4 | H17: 46240 | I17: Fail | J17: Hệ thống báo lỗi "Có lỗi xảy ra. Kiểm tra lại đăng nhập hoặc dữ liệu nhập." | K17: 46240 | L17: Pass | M17: TCDsAdminRetest4_1, TCDsAdminRetest4_2
A18: 3. Kiểm tra các trường bắt buộc
A19: TC-DS-ADMIN-005 | B19: Kiểm tra hệ thống xử lý khi Admin không chọn bác sĩ. | C19: 1: Đăng nhập với vai trò Admin. 2: Mở trang Quản lý lịch làm việc bác sĩ. 3: Giữ trường Bác sĩ ở giá trị -- Chọn bác sĩ --. 4: Chọn ngày làm việc hợp lệ. 5: Giữ nguyên ca và trạng thái mặc định. 6: Nhấn Thêm lịch. 7: Kiểm tra phản hồi tại trường Bác sĩ và Danh sách lịch làm việc. | D19: Hệ thống yêu cầu chọn bác sĩ và không tạo lịch mới. | G19: TCDsAdmin5 | H19: 46240 | I19: Pass | J19: Có thông báo chặn thao tác do trường Bác sĩ là bắt buộc.
A20: TC-DS-ADMIN-006 | B20: Kiểm tra hệ thống xử lý khi Admin không chọn ngày làm việc. | C20: 1: Đăng nhập với vai trò Admin. 2: Mở trang Quản lý lịch làm việc bác sĩ. 3: Chọn một bác sĩ. 4: Để trống trường Ngày làm việc. 5: Giữ nguyên ca và trạng thái mặc định. 6: Nhấn Thêm lịch. 7: Kiểm tra phản hồi tại trường Ngày làm việc và Danh sách lịch làm việc. | D20: Hệ thống yêu cầu chọn ngày làm việc và không tạo lịch mới. | G20: TCDsAdmin6 | H20: 46240 | I20: Pass | J20: Có thông báo chặn thao tác do trường Ngày làm việc là bắt buộc.
A21: 4. Kiểm tra ngày làm việc
A22: TC-DS-ADMIN-007 | B22: Kiểm tra hệ thống không cho phép Admin tạo lịch làm việc cho ngày đã qua. | C22: 1: Đăng nhập với vai trò Admin. 2: Mở trang Quản lý lịch làm việc bác sĩ. 3: Chọn một bác sĩ. 4: Chọn một ngày trước ngày hiện tại. 5: Chọn ca và trạng thái hợp lệ. 6: Nhấn Thêm lịch. 7: Kiểm tra thông báo và Danh sách lịch làm việc. | D22: Hệ thống không tạo lịch cho ngày đã qua và hiển thị thông báo ngày làm việc không hợp lệ. | G22: TCDsAdmin7_1, TCDsAdmin7_2 | H22: 46240 | I22: Fail | J22: Hệ thống vẫn cho phép thêm lịch ngày 01/08/2026 và hiển thị thông báo ‘Thêm lịch làm việc thành công!’. Không có validation ngăn ngày làm việc đã qua
A23: 5. Kiểm tra trùng và xung đột lịch làm việc
